2023-07-04 10:45:48,807 INFO    Thread-11 (_run_job):12346 [wandb_setup.py:_flush():76] Current SDK version is 0.15.4
2023-07-04 10:45:48,808 INFO    Thread-11 (_run_job):12346 [wandb_setup.py:_flush():76] Configure stats pid to 12346
2023-07-04 10:45:48,808 INFO    Thread-11 (_run_job):12346 [wandb_setup.py:_flush():76] Loading settings from /home/zhangx18/.config/wandb/settings
2023-07-04 10:45:48,808 INFO    Thread-11 (_run_job):12346 [wandb_setup.py:_flush():76] Loading settings from /scratch/work/zhangx18/reproduced-nam/mynam/wandb/settings
2023-07-04 10:45:48,808 INFO    Thread-11 (_run_job):12346 [wandb_setup.py:_flush():76] Loading settings from environment variables: {'project': 'nam-sweep-fig-test', 'entity': 'xinyu-zhang', 'root_dir': '/scratch/work/zhangx18/reproduced-nam/mynam', 'run_id': 'qk5lfl4y', 'sweep_param_path': '/scratch/work/zhangx18/reproduced-nam/mynam/wandb/sweep-h2bgdbww/config-qk5lfl4y.yaml', 'sweep_id': 'h2bgdbww'}
2023-07-04 10:45:48,809 INFO    Thread-11 (_run_job):12346 [wandb_setup.py:_flush():76] Applying setup settings: {'_disable_service': False}
2023-07-04 10:45:48,809 INFO    Thread-11 (_run_job):12346 [wandb_setup.py:_flush():76] Inferring run settings from compute environment: {'program': '<python with no main file>'}
2023-07-04 10:45:48,809 INFO    Thread-11 (_run_job):12346 [wandb_init.py:_log_setup():507] Logging user logs to /scratch/work/zhangx18/reproduced-nam/mynam/wandb/run-20230704_104548-qk5lfl4y/logs/debug.log
2023-07-04 10:45:48,809 INFO    Thread-11 (_run_job):12346 [wandb_init.py:_log_setup():508] Logging internal logs to /scratch/work/zhangx18/reproduced-nam/mynam/wandb/run-20230704_104548-qk5lfl4y/logs/debug-internal.log
2023-07-04 10:45:48,809 INFO    Thread-11 (_run_job):12346 [wandb_init.py:_jupyter_setup():453] configuring jupyter hooks <wandb.sdk.wandb_init._WandbInit object at 0x2b3fe4977df0>
2023-07-04 10:45:48,810 INFO    Thread-11 (_run_job):12346 [wandb_init.py:init():547] calling init triggers
2023-07-04 10:45:48,810 INFO    Thread-11 (_run_job):12346 [wandb_init.py:init():554] wandb.init called with sweep_config: {'lr': 0.012451161898745214}
config: {}
2023-07-04 10:45:48,810 INFO    Thread-11 (_run_job):12346 [wandb_init.py:init():596] starting backend
2023-07-04 10:45:48,810 INFO    Thread-11 (_run_job):12346 [wandb_init.py:init():600] setting up manager
2023-07-04 10:45:48,822 INFO    Thread-11 (_run_job):12346 [backend.py:_multiprocessing_setup():106] multiprocessing start_methods=fork,spawn,forkserver, using: spawn
2023-07-04 10:45:48,833 INFO    Thread-11 (_run_job):12346 [wandb_init.py:init():606] backend started and connected
2023-07-04 10:45:48,859 INFO    Thread-11 (_run_job):12346 [wandb_run.py:_config_callback():1283] config_cb None None {'lr': 0.012451161898745214}
2023-07-04 10:45:48,861 INFO    Thread-11 (_run_job):12346 [wandb_run.py:_label_probe_notebook():1235] probe notebook
2023-07-04 10:45:48,861 INFO    Thread-11 (_run_job):12346 [wandb_run.py:_label_probe_notebook():1245] Unable to probe notebook: 'NoneType' object has no attribute 'get'
2023-07-04 10:45:48,861 INFO    Thread-11 (_run_job):12346 [wandb_init.py:init():703] updated telemetry
2023-07-04 10:45:48,876 INFO    Thread-11 (_run_job):12346 [wandb_init.py:init():736] communicating run to backend with 60.0 second timeout
2023-07-04 10:45:49,302 INFO    Thread-11 (_run_job):12346 [wandb_run.py:_on_init():2176] communicating current version
2023-07-04 10:45:49,353 INFO    Thread-11 (_run_job):12346 [wandb_run.py:_on_init():2185] got version response 
2023-07-04 10:45:49,353 INFO    Thread-11 (_run_job):12346 [wandb_init.py:init():787] starting run threads in backend
2023-07-04 10:46:13,353 INFO    Thread-11 (_run_job):12346 [wandb_run.py:_finish():1890] finishing run xinyu-zhang/nam-sweep-fig-test/qk5lfl4y
2023-07-04 10:46:13,353 INFO    Thread-11 (_run_job):12346 [jupyter.py:save_history():445] not saving jupyter history
2023-07-04 10:46:13,353 INFO    Thread-11 (_run_job):12346 [jupyter.py:save_ipynb():373] not saving jupyter notebook
2023-07-04 10:46:13,353 INFO    Thread-11 (_run_job):12346 [wandb_init.py:_jupyter_teardown():435] cleaning up jupyter logic
2023-07-04 10:46:13,353 INFO    Thread-11 (_run_job):12346 [wandb_run.py:_atexit_cleanup():2124] got exitcode: 0
2023-07-04 10:46:13,353 INFO    Thread-11 (_run_job):12346 [wandb_run.py:_restore():2107] restore
2023-07-04 10:46:13,353 INFO    Thread-11 (_run_job):12346 [wandb_run.py:_restore():2113] restore done
2023-07-04 10:46:13,354 INFO    Thread-11 (_run_job):12346 [wandb_run.py:_restore():2107] restore
2023-07-04 10:46:13,354 INFO    Thread-11 (_run_job):12346 [wandb_run.py:_restore():2113] restore done
2023-07-04 10:46:14,356 ERROR   Thread-11 (_run_job):12346 [wandb_run.py:_atexit_cleanup():2145] Problem finishing run
Traceback (most recent call last):
  File "/share/apps/anaconda-ci/fgci-centos7-anaconda/software/anaconda/2023-02/d63245c4/lib/python3.10/site-packages/wandb/sdk/wandb_init.py", line 1152, in init
    run = wi.init()
  File "/share/apps/anaconda-ci/fgci-centos7-anaconda/software/anaconda/2023-02/d63245c4/lib/python3.10/site-packages/wandb/sdk/wandb_init.py", line 827, in init
    run._on_start()
  File "/share/apps/anaconda-ci/fgci-centos7-anaconda/software/anaconda/2023-02/d63245c4/lib/python3.10/site-packages/wandb/sdk/wandb_run.py", line 2194, in _on_start
    self._header(
  File "/share/apps/anaconda-ci/fgci-centos7-anaconda/software/anaconda/2023-02/d63245c4/lib/python3.10/site-packages/wandb/sdk/wandb_run.py", line 3079, in _header
    Run._header_wandb_version_info(settings=settings, printer=printer)
  File "/share/apps/anaconda-ci/fgci-centos7-anaconda/software/anaconda/2023-02/d63245c4/lib/python3.10/site-packages/wandb/sdk/wandb_run.py", line 3112, in _header_wandb_version_info
    printer.display(
  File "/share/apps/anaconda-ci/fgci-centos7-anaconda/software/anaconda/2023-02/d63245c4/lib/python3.10/site-packages/wandb/sdk/lib/printer.py", line 68, in display
    self._display(text, level=level, default_text=default_text)
  File "/share/apps/anaconda-ci/fgci-centos7-anaconda/software/anaconda/2023-02/d63245c4/lib/python3.10/site-packages/wandb/sdk/lib/printer.py", line 240, in _display
    self._display_fn_mapping(level)(text)
  File "/share/apps/anaconda-ci/fgci-centos7-anaconda/software/anaconda/2023-02/d63245c4/lib/python3.10/site-packages/wandb/sdk/lib/ipython.py", line 74, in display_html
    return display(HTML(html))
  File "/share/apps/anaconda-ci/fgci-centos7-anaconda/software/anaconda/2023-02/d63245c4/lib/python3.10/site-packages/IPython/core/display_functions.py", line 305, in display
    publish_display_data(data=format_dict, metadata=md_dict, **kwargs)
  File "/share/apps/anaconda-ci/fgci-centos7-anaconda/software/anaconda/2023-02/d63245c4/lib/python3.10/site-packages/IPython/core/display_functions.py", line 93, in publish_display_data
    display_pub.publish(
  File "/share/apps/anaconda-ci/fgci-centos7-anaconda/software/anaconda/2023-02/d63245c4/lib/python3.10/site-packages/wandb/sdk/wandb_init.py", line 464, in publish
    ipython.display_pub._orig_publish(data, metadata=metadata, **kwargs)
  File "/share/apps/anaconda-ci/fgci-centos7-anaconda/software/anaconda/2023-02/d63245c4/lib/python3.10/site-packages/ipykernel/zmqshell.py", line 102, in publish
    self._flush_streams()
  File "/share/apps/anaconda-ci/fgci-centos7-anaconda/software/anaconda/2023-02/d63245c4/lib/python3.10/site-packages/ipykernel/zmqshell.py", line 65, in _flush_streams
    sys.stdout.flush()
  File "/share/apps/anaconda-ci/fgci-centos7-anaconda/software/anaconda/2023-02/d63245c4/lib/python3.10/site-packages/ipykernel/iostream.py", line 557, in flush
    self.pub_thread.schedule(self._flush)
  File "/share/apps/anaconda-ci/fgci-centos7-anaconda/software/anaconda/2023-02/d63245c4/lib/python3.10/site-packages/ipykernel/iostream.py", line 249, in schedule
    self._event_pipe.send(b"")
  File "/share/apps/anaconda-ci/fgci-centos7-anaconda/software/anaconda/2023-02/d63245c4/lib/python3.10/site-packages/zmq/sugar/socket.py", line 696, in send
    return super().send(data, flags=flags, copy=copy, track=track)
  File "zmq/backend/cython/socket.pyx", line 742, in zmq.backend.cython.socket.Socket.send
  File "zmq/backend/cython/socket.pyx", line 783, in zmq.backend.cython.socket.Socket.send
  File "zmq/backend/cython/socket.pyx", line 138, in zmq.backend.cython.socket._check_closed
zmq.error.ZMQError: Socket operation on non-socket

During handling of the above exception, another exception occurred:

Traceback (most recent call last):
  File "/share/apps/anaconda-ci/fgci-centos7-anaconda/software/anaconda/2023-02/d63245c4/lib/python3.10/site-packages/wandb/sdk/wandb_init.py", line 1160, in init
    getcaller()
  File "/share/apps/anaconda-ci/fgci-centos7-anaconda/software/anaconda/2023-02/d63245c4/lib/python3.10/site-packages/wandb/sdk/wandb_init.py", line 836, in getcaller
    print("Problem at:", src, line, func)
  File "/share/apps/anaconda-ci/fgci-centos7-anaconda/software/anaconda/2023-02/d63245c4/lib/python3.10/site-packages/ipykernel/iostream.py", line 646, in write
    self._schedule_flush()
  File "/share/apps/anaconda-ci/fgci-centos7-anaconda/software/anaconda/2023-02/d63245c4/lib/python3.10/site-packages/ipykernel/iostream.py", line 543, in _schedule_flush
    self.pub_thread.schedule(_schedule_in_thread)
  File "/share/apps/anaconda-ci/fgci-centos7-anaconda/software/anaconda/2023-02/d63245c4/lib/python3.10/site-packages/ipykernel/iostream.py", line 249, in schedule
    self._event_pipe.send(b"")
  File "/share/apps/anaconda-ci/fgci-centos7-anaconda/software/anaconda/2023-02/d63245c4/lib/python3.10/site-packages/zmq/sugar/socket.py", line 696, in send
    return super().send(data, flags=flags, copy=copy, track=track)
  File "zmq/backend/cython/socket.pyx", line 742, in zmq.backend.cython.socket.Socket.send
  File "zmq/backend/cython/socket.pyx", line 783, in zmq.backend.cython.socket.Socket.send
  File "zmq/backend/cython/socket.pyx", line 138, in zmq.backend.cython.socket._check_closed
zmq.error.ZMQError: Socket operation on non-socket

The above exception was the direct cause of the following exception:

Traceback (most recent call last):
  File "/share/apps/anaconda-ci/fgci-centos7-anaconda/software/anaconda/2023-02/d63245c4/lib/python3.10/site-packages/wandb/agents/pyagent.py", line 298, in _run_job
    self._function()
  File "/scratch/work/zhangx18/reproduced-nam/mynam/trainer/wandbtrainer.py", line 38, in sweep_train
    run = wandb.init()
  File "/share/apps/anaconda-ci/fgci-centos7-anaconda/software/anaconda/2023-02/d63245c4/lib/python3.10/site-packages/wandb/sdk/wandb_init.py", line 1190, in init
    raise Error("An unexpected error occurred") from error_seen
wandb.errors.Error: An unexpected error occurred

During handling of the above exception, another exception occurred:

Traceback (most recent call last):
  File "/share/apps/anaconda-ci/fgci-centos7-anaconda/software/anaconda/2023-02/d63245c4/lib/python3.10/site-packages/wandb/sdk/wandb_run.py", line 2133, in _atexit_cleanup
    self._on_finish()
  File "/share/apps/anaconda-ci/fgci-centos7-anaconda/software/anaconda/2023-02/d63245c4/lib/python3.10/site-packages/wandb/sdk/wandb_run.py", line 2368, in _on_finish
    self._footer_exit_status_info(
  File "/share/apps/anaconda-ci/fgci-centos7-anaconda/software/anaconda/2023-02/d63245c4/lib/python3.10/site-packages/wandb/sdk/wandb_run.py", line 3271, in _footer_exit_status_info
    printer.display(f'{" ".join(info)}')
  File "/share/apps/anaconda-ci/fgci-centos7-anaconda/software/anaconda/2023-02/d63245c4/lib/python3.10/site-packages/wandb/sdk/lib/printer.py", line 68, in display
    self._display(text, level=level, default_text=default_text)
  File "/share/apps/anaconda-ci/fgci-centos7-anaconda/software/anaconda/2023-02/d63245c4/lib/python3.10/site-packages/wandb/sdk/lib/printer.py", line 240, in _display
    self._display_fn_mapping(level)(text)
  File "/share/apps/anaconda-ci/fgci-centos7-anaconda/software/anaconda/2023-02/d63245c4/lib/python3.10/site-packages/wandb/sdk/lib/ipython.py", line 74, in display_html
    return display(HTML(html))
  File "/share/apps/anaconda-ci/fgci-centos7-anaconda/software/anaconda/2023-02/d63245c4/lib/python3.10/site-packages/IPython/core/display_functions.py", line 305, in display
    publish_display_data(data=format_dict, metadata=md_dict, **kwargs)
  File "/share/apps/anaconda-ci/fgci-centos7-anaconda/software/anaconda/2023-02/d63245c4/lib/python3.10/site-packages/IPython/core/display_functions.py", line 93, in publish_display_data
    display_pub.publish(
  File "/share/apps/anaconda-ci/fgci-centos7-anaconda/software/anaconda/2023-02/d63245c4/lib/python3.10/site-packages/ipykernel/zmqshell.py", line 102, in publish
    self._flush_streams()
  File "/share/apps/anaconda-ci/fgci-centos7-anaconda/software/anaconda/2023-02/d63245c4/lib/python3.10/site-packages/ipykernel/zmqshell.py", line 65, in _flush_streams
    sys.stdout.flush()
  File "/share/apps/anaconda-ci/fgci-centos7-anaconda/software/anaconda/2023-02/d63245c4/lib/python3.10/site-packages/ipykernel/iostream.py", line 557, in flush
    self.pub_thread.schedule(self._flush)
  File "/share/apps/anaconda-ci/fgci-centos7-anaconda/software/anaconda/2023-02/d63245c4/lib/python3.10/site-packages/ipykernel/iostream.py", line 249, in schedule
    self._event_pipe.send(b"")
  File "/share/apps/anaconda-ci/fgci-centos7-anaconda/software/anaconda/2023-02/d63245c4/lib/python3.10/site-packages/zmq/sugar/socket.py", line 696, in send
    return super().send(data, flags=flags, copy=copy, track=track)
  File "zmq/backend/cython/socket.pyx", line 742, in zmq.backend.cython.socket.Socket.send
  File "zmq/backend/cython/socket.pyx", line 783, in zmq.backend.cython.socket.Socket.send
  File "zmq/backend/cython/socket.pyx", line 138, in zmq.backend.cython.socket._check_closed
zmq.error.ZMQError: Socket operation on non-socket
2023-07-04 10:47:46,735 INFO    MainThread:12346 [wandb_setup.py:_flush():76] Current SDK version is 0.15.4
2023-07-04 10:47:46,736 INFO    MainThread:12346 [wandb_setup.py:_flush():76] Configure stats pid to 12346
2023-07-04 10:47:46,737 INFO    MainThread:12346 [wandb_setup.py:_flush():76] Loading settings from /home/zhangx18/.config/wandb/settings
2023-07-04 10:47:46,737 INFO    MainThread:12346 [wandb_setup.py:_flush():76] Loading settings from /scratch/work/zhangx18/reproduced-nam/mynam/wandb/settings
2023-07-04 10:47:46,737 INFO    MainThread:12346 [wandb_setup.py:_flush():76] Loading settings from environment variables: {'project': 'nam-sweep-fig-test', 'entity': 'xinyu-zhang', 'root_dir': '/scratch/work/zhangx18/reproduced-nam/mynam', 'run_id': 'qk5lfl4y', 'sweep_param_path': '/scratch/work/zhangx18/reproduced-nam/mynam/wandb/sweep-h2bgdbww/config-qk5lfl4y.yaml', 'sweep_id': 'h2bgdbww'}
2023-07-04 10:47:46,737 INFO    MainThread:12346 [wandb_setup.py:_flush():76] Applying setup settings: {'_disable_service': False}
2023-07-04 10:47:46,737 INFO    MainThread:12346 [wandb_setup.py:_flush():76] Inferring run settings from compute environment: {'program': '<python with no main file>'}
2023-07-04 10:47:46,737 INFO    MainThread:12346 [wandb_init.py:_log_setup():507] Logging user logs to /scratch/work/zhangx18/reproduced-nam/mynam/wandb/run-20230704_104746-qk5lfl4y/logs/debug.log
2023-07-04 10:47:46,737 INFO    MainThread:12346 [wandb_init.py:_log_setup():508] Logging internal logs to /scratch/work/zhangx18/reproduced-nam/mynam/wandb/run-20230704_104746-qk5lfl4y/logs/debug-internal.log
2023-07-04 10:47:46,738 INFO    MainThread:12346 [wandb_init.py:_jupyter_setup():453] configuring jupyter hooks <wandb.sdk.wandb_init._WandbInit object at 0x2b3fe5024af0>
2023-07-04 10:47:46,738 INFO    MainThread:12346 [wandb_init.py:init():547] calling init triggers
2023-07-04 10:47:46,738 INFO    MainThread:12346 [wandb_init.py:init():554] wandb.init called with sweep_config: {'lr': 0.012451161898745214}
config: {}
2023-07-04 10:47:46,738 INFO    MainThread:12346 [wandb_init.py:init():571] re-initializing run, found existing run on stack: qk5lfl4y
2023-07-04 10:47:46,740 INFO    MainThread:12346 [wandb_run.py:_finish():1890] finishing run xinyu-zhang/nam-sweep-fig-test/qk5lfl4y
2023-07-04 10:47:46,740 INFO    MainThread:12346 [jupyter.py:save_history():445] not saving jupyter history
2023-07-04 10:47:46,740 INFO    MainThread:12346 [jupyter.py:save_ipynb():373] not saving jupyter notebook
2023-07-04 10:47:46,741 INFO    MainThread:12346 [wandb_init.py:_jupyter_teardown():435] cleaning up jupyter logic
